<?xml version="1.0" ?>
<!-- =================================================================================== -->
<!-- |    This document was autogenerated by xacro from trike.urdf.xacro               | -->
<!-- |    EDITING THIS FILE BY HAND IS NOT RECOMMENDED                                 | -->
<!-- =================================================================================== -->
<robot name="trike">
  <!-- 55 degrees in radians -->
  <!-- Base link (reference point) -->
  <link name="base_link">
    <visual>
      <geometry>
        <box size="0.5 0.3 0.1"/>
      </geometry>
      <material name="gray">
        <color rgba="0.5 0.5 0.5 1.0"/>
      </material>
    </visual>
  </link>
  <!-- rear wheel -->
  <link name="rear_wheel">
    <visual>
      <geometry>
        <cylinder length="0.076" radius="0.24"/>
      </geometry>
      <material name="black">
        <color rgba="0.0 0.0 0.0 1.0"/>
      </material>
    </visual>
  </link>
  <joint name="rear_wheel_joint" type="fixed">
    <parent link="base_link"/>
    <child link="rear_wheel"/>
    <origin xyz="0 0 -0.24"/>
  </joint>
  <!-- Front Frame (Extending to Steering) -->
  <link name="front_frame">
    <visual>
      <geometry>
        <box size="2.44 0.1 0.1"/>
      </geometry>
      <material name="blue">
        <color rgba="0.0 0.0 1.0 1.0"/>
      </material>
    </visual>
  </link>
  <joint name="frame_joint" type="fixed">
    <parent link="base_link"/>
    <child link="front_frame"/>
    <origin xyz="1.22 0 0"/>
  </joint>
  <!-- Steering Mechanism -->
  <link name="steering_bar"/>
  <joint name="steering_joint" type="revolute">
    <parent link="front_frame"/>
    <child link="steering_bar"/>
    <origin xyz="1.22 0 0.1"/>
    <axis xyz="0 0 1"/>
    <limit effort="1.0" lower="-0.96" upper="0.96" velocity="1.0"/>
  </joint>
  <!-- Front Wheels -->
  <link name="front_left_wheel">
    <visual>
      <geometry>
        <cylinder length="0.076" radius="0.24"/>
      </geometry>
    </visual>
  </link>
  <link name="front_right_wheel">
    <visual>
      <geometry>
        <cylinder length="0.076" radius="0.24"/>
      </geometry>
    </visual>
  </link>
  <!-- Front Wheel Joints (Connected to Steering Bar) -->
  <joint name="front_left_wheel_joint" type="revolute">
    <parent link="steering_bar"/>
    <child link="front_left_wheel"/>
    <origin xyz="1.22 0.305 -0.24"/>
    <axis xyz="0 1 0"/>
    <limit effort="10.0" lower="-1.57" upper="1.57" velocity="1.0"/>
  </joint>
  <joint name="front_right_wheel_joint" type="revolute">
    <parent link="steering_bar"/>
    <child link="front_right_wheel"/>
    <origin xyz="1.22 -0.305 -0.24"/>
    <axis xyz="0 1 0"/>
    <limit effort="10.0" lower="-1.57" upper="1.57" velocity="1.0"/>
  </joint>
</robot>
